2023-05-15 11:55:06.851222: W external/org_tensorflow/tensorflow/tsl/platform/default/dso_loader.cc:66] Could not load dynamic library 'libcudart.so.11.0'; dlerror: libcudart.so.11.0: cannot open shared object file: No such file or directory; LD_LIBRARY_PATH: /storage/icds/RISE/sw8/julia-1.8.1/julia-1.8.1/lib:/storage/icds/RISE/sw8/anaconda/anaconda3/lib
2023-05-15 11:55:07.243066: W external/org_tensorflow/tensorflow/tsl/platform/default/dso_loader.cc:66] Could not load dynamic library 'libcudart.so.11.0'; dlerror: libcudart.so.11.0: cannot open shared object file: No such file or directory; LD_LIBRARY_PATH: /storage/icds/RISE/sw8/julia-1.8.1/julia-1.8.1/lib:/storage/icds/RISE/sw8/anaconda/anaconda3/lib
2023-05-15 11:55:07.266079: W external/org_tensorflow/tensorflow/tsl/platform/default/dso_loader.cc:66] Could not load dynamic library 'libcudart.so.11.0'; dlerror: libcudart.so.11.0: cannot open shared object file: No such file or directory; LD_LIBRARY_PATH: /storage/icds/RISE/sw8/julia-1.8.1/julia-1.8.1/lib:/storage/icds/RISE/sw8/anaconda/anaconda3/lib
2023-05-15 11:55:08.356964: W external/org_tensorflow/tensorflow/tsl/platform/default/dso_loader.cc:66] Could not load dynamic library 'libcuda.so.1'; dlerror: libcuda.so.1: cannot open shared object file: No such file or directory; LD_LIBRARY_PATH: /storage/icds/RISE/sw8/julia-1.8.1/julia-1.8.1/lib:/storage/icds/RISE/sw8/anaconda/anaconda3/lib
2023-05-15 11:55:08.356984: W external/org_tensorflow/tensorflow/compiler/xla/stream_executor/cuda/cuda_driver.cc:265] failed call to cuInit: UNKNOWN ERROR (303)
WARNING:jax._src.lib.xla_bridge:No GPU/TPU found, falling back to CPU. (Set TF_CPP_MIN_LOG_LEVEL=0 and rerun for more info.)
Traceback (most recent call last):
  File "/storage/work/jvz5625/SONG/gp_parallel.py", line 20, in <module>
    ACF = sm.tsa.acovf(y[i,:], fft=True)
  File "/storage/home/jvz5625/.local/lib/python3.10/site-packages/jax/_src/numpy/lax_numpy.py", line 3815, in _rewriting_take
    return _gather(arr, treedef, static_idx, dynamic_idx, indices_are_sorted,
  File "/storage/home/jvz5625/.local/lib/python3.10/site-packages/jax/_src/numpy/lax_numpy.py", line 3824, in _gather
    indexer = _index_to_gather(shape(arr), idx)  # shared with _scatter_update
  File "/storage/home/jvz5625/.local/lib/python3.10/site-packages/jax/_src/numpy/lax_numpy.py", line 3925, in _index_to_gather
    idx = _canonicalize_tuple_index(len(x_shape), idx)
  File "/storage/home/jvz5625/.local/lib/python3.10/site-packages/jax/_src/numpy/lax_numpy.py", line 4258, in _canonicalize_tuple_index
    raise IndexError(
IndexError: Too many indices for array: 2 non-None/Ellipsis indices for dim 1.
